Workbook

Sheet Cover
B2: Does M&A Create Value? Long-Run Performance of US Acquirers
B3: Alessandro Radice · data to 31 March 2025 · SEC EDGAR, DoltHub, Kenneth French data library
B5: Sheet | D5: What it holds
B6: Inputs | D6: Horizon, benchmark and filters that drive every live result
B7: Deals | D7: 786 acquisitions completed 2012-2021, one row each, with the BHAR as a live formula
B8: Returns | D8: Monthly returns of each acquirer and of its size/book-to-market benchmark, months 1 to 60 after completion
B9: Summary | D9: Mean, median, share positive and t-statistic, overall and by payment method, from the Deals sheet
B10: Calendar time | D10: Monthly portfolio of recent acquirers and its alpha against the Fama-French factors (LINEST)
B11: Operating | D11: Industry-adjusted operating return on assets before and after, the regression of post on pre, goodwill impairments
B12: Checks | D12: Every headline number recomputed in Excel and compared with the Python engine
B14: Colour code: blue = input, black = formula, green = link to another sheet. Educational project, not investment advice.
B16: Headline results (live)
B17: Mean 36-month BHAR | C17: =Summary!D9 -> -0.12392209
B18: Median 36-month BHAR | C18: =Summary!E9 -> -0.21343492
B19: FF5 + momentum alpha, annualized | C19: ='Calendar time'!P10 -> -0.022410138
B20: Checks | C20: =Checks!F16 -> OK

Sheet Inputs
B2: Inputs
B3: Change the blue cells; every sheet recalculates
B5: Input | C5: Value | D5: Notes
B6: Horizon (months after completion) | C6: 36 | D6: 12, 24, 36 or 60. 60 months only for deals completed by March 2020
B7: Benchmark (1 = value-weighted, 2 = equal-weighted) | C7: 1 | D7: Fama-French 25 portfolios formed on size and book-to-market
B8: Minimum deal size (% of acquirer market value) | C8: 0.1 | D8: The sample is built at 10%; raise it to study larger deals
B9: Payment method filter | C9: All | D9: All, Cash, Mixed or Stock-heavy
B10: Completion year from | C10: 2012
B11: Completion year to | C11: 2021
B13: Definitions
B14: BHAR = (1+r1)(1+r2)...(1+rH) - (1+b1)(1+b2)...(1+bH): the buy-and-hold return of the acquirer minus that of its benchmark portfolio.
B15: Month 1 is the first full month after the month of completion (the 8-K Item 2.01 filing).
B16: If the acquirer stops trading (acquired, delisted), the remaining months earn the benchmark: the BHAR is frozen, not dropped.
B17: Payment: Cash = stock under 5% of the price paid; Stock-heavy = 50% or more; Mixed in between (XBRL cash-flow and equity statements).
B18: Deal size = deal value / acquirer market value at the end of the month before completion.

Sheet Returns
B2: Returns
B3: Monthly total returns; acquirer after delisting = benchmark; blank after March 2025
D5: Acquirer | BM5: Benchmark, value-weighted | DV5: Benchmark, equal-weighted
B6: Deal | C6: Traded in month 1 | D6: 1 | E6: 2 | F6: 3 | G6: 4 | H6: 5 | I6: 6 | J6: 7 | K6: 8 | L6: 9 | M6: 10 | N6: 11 | O6: 12 | P6: 13 | Q6: 14 | R6: 15 | S6: 16 | T6: 17 | U6: 18 | V6: 19 | W6: 20 | X6: 21 | Y6: 22 | Z6: 23 | AA6: 24 | AB6: 25 | AC6: 26 | AD6: 27 | AE6: 28 | AF6: 29 | AG6: 30 | AH6: 31 | AI6: 32 | AJ6: 33 | AK6: 34 | AL6: 35 | AM6: 36 | AN6: 37 | AO6: 38 | AP6: 39 | AQ6: 40 | AR6: 41 | AS6: 42 | AT6: 43 | AU6: 44 | AV6: 45 | AW6: 46 | AX6: 47 | AY6: 48 | AZ6: 49 | BA6: 50 | BB6: 51 | BC6: 52 | BD6: 53 | BE6: 54 | BF6: 55 | BG6: 56 | BH6: 57 | BI6: 58 | BJ6: 59 | BK6: 60 | BM6: 1 | BN6: 2 | BO6: 3 | BP6: 4 | BQ6: 5 | BR6: 6 | BS6: 7 | BT6: 8 | BU6: 9 | BV6: 10 | BW6: 11 | BX6: 12 | BY6: 13 | BZ6: 14 | CA6: 15 | CB6: 16 | CC6: 17 | CD6: 18 | CE6: 19 | CF6: 20 | CG6: 21 | CH6: 22 | CI6: 23 | CJ6: 24 | CK6: 25 | CL6: 26 | CM6: 27 | CN6: 28 | CO6: 29 | CP6: 30 | CQ6: 31 | CR6: 32 | CS6: 33 | CT6: 34 | CU6: 35 | CV6: 36 | CW6: 37 | CX6: 38 | CY6: 39 | CZ6: 40 | DA6: 41 | DB6: 42 | DC6: 43 | DD6: 44 | DE6: 45 | DF6: 46 | DG6: 47 | DH6: 48 | DI6: 49 | DJ6: 50 | DK6: 51 | DL6: 52 | DM6: 53 | DN6: 54 | DO6: 55 | DP6: 56 | DQ6: 57 | DR6: 58 | DS6: 59 | DT6: 60 | DV6: 1 | DW6: 2 | DX6: 3 | DY6: 4 | DZ6: 5 | EA6: 6 | EB6: 7 | EC6: 8 | ED6: 9 | EE6: 10 | EF6: 11 | EG6: 12 | EH6: 13 | EI6: 14 | EJ6: 15 | EK6: 16 | EL6: 17 | EM6: 18 | EN6: 19 | EO6: 20 | EP6: 21 | EQ6: 22 | ER6: 23 | ES6: 24 | ET6: 25 | EU6: 26 | EV6: 27 | EW6: 28 | EX6: 29 | EY6: 30 | EZ6: 31 | FA6: 32 | FB6: 33 | FC6: 34 | FD6: 35 | FE6: 36 | FF6: 37 | FG6: 38 | FH6: 39 | FI6: 40 | FJ6: 41 | FK6: 42 | FL6: 43 | FM6: 44 | FN6: 45 | FO6: 46 | FP6: 47 | FQ6: 48 | FR6: 49 | FS6: 50 | FT6: 51 | FU6: 52 | FV6: 53 | FW6: 54 | FX6: 55 | FY6: 56 | FZ6: 57 | GA6: 58 | GB6: 59 | GC6: 60
B7: =Deals!B7 -> Cabot Corp | C7: 1 | D7: 0.119061 | E7: 0.053567 | F7: 0.010544 | G7: -0.12358 | H7: 0.07672 | I7: -0.041769 | J7: -0.106923 | K7: 0.049957 | L7: -0.022149 | M7: 0.055089 | N7: 0.054598 | O7: -0.059311 | P7: -0.017366 | Q7: -0.070147 | R7: 0.098246 | S7: 0.089989 | T7: -0.085979 | U7: 0.096205 | V7: -0.02511 | W7: 0.068017 | X7: 0.091314 | Y7: 0.043767 | Z7: 0.056526 | AA7: -0.053113 | AB7: 0.11239 | AC7: 0.090876 | AD7: -0.021334 | AE7: -0.021626 | AF7: 0.025464 | AG7: -0.096568 | AH7: 0.045619 | AI7: -0.073202 | AJ7: -0.085484 | AK7: -0.072152 | AL7: 0.018106 | AM7: -0.03306 | AN7: 0.0639 | AO7: -0.00266 | AP7: -0.050222 | AQ7: -0.029715 | AR7: -0.100796 | AS7: -0.056584 | AT7: -0.037237 | AU7: -0.068202 | AV7: 0.138783 | AW7: 0.211464 | AX7: -0.061093 | AY7: -0.013209 | AZ7: 0.103867 | BA7: 0.085336 | BB7: 0.009518 | BC7: -0.063128 | BD7: -0.001094 | BE7: 0.06636 | BF7: 0.02403 | BG7: 0.051143 | BH7: -0.005152 | BI7: -0.023207 | BJ7: -0.007658 | BK7: 0.095568 | BM7: 0.038859 | BN7: 0.017779 | BO7: -0.009457 | BP7: -0.061153 | BQ7: 0.023912 | BR7: 0.004514 | BS7: 0.042119 | BT7: 0.031368 | BU7: 0.010094 | BV7: 0.020912 | BW7: 0.028549 | BX7: 0.071309 | BY7: 0.026138 | BZ7: 0.036034 | CA7: -0.008356 | CB7: 0.050238 | CC7: -0.007612 | CD7: 0.07738 | CE7: -0.046876 | CF7: 0.055928 | CG7: 0.042349 | CH7: 0.025847 | CI7: 0.036152 | CJ7: -0.026369 | CK7: 0.069644 | CL7: 0.013672 | CM7: -0.014688 | CN7: 0.00594 | CO7: 0.04965 | CP7: -0.064442 | CQ7: 0.055168 | CR7: -0.066219 | CS7: 0.04088 | CT7: 0.001903 | CU7: 0.01593 | CV7: -0.046629 | CW7: 0.060563 | CX7: 0.011549 | CY7: -0.01011 | CZ7: 0.020129 | DA7: -0.019694 | DB7: -0.035205 | DC7: -0.050275 | DD7: -0.05851 | DE7: 0.049146 | DF7: 0.029941 | DG7: -0.057563 | DH7: -0.064508 | DI7: 0.009635 | DJ7: 0.103282 | DK7: 0.033338 | DL7: 0.009363 | DM7: -0.008015 | DN7: 0.041571 | DO7: 0.021929 | DP7: 0.013879 | DQ7: -0.028352 | DR7: 0.132419 | DS7: 0.021499 | DT7: -0.001631 | DV7: 0.041584 | DW7: 0.019052 | DX7: -0.012578 | DY7: -0.063155 | DZ7: 0.023735 | EA7: 0.001745 | EB7: 0.041711 | EC7: 0.029139 | ED7: 0.007073 | EE7: 0.018115 | EF7: 0.035914 | EG7: 0.069168 | EH7: 0.021522 | EI7: 0.039946 | EJ7: 0.00271 | EK7: 0.046562 | EL7: -0.007702 | EM7: 0.077152 | EN7: -0.049581 | EO7: 0.056228 | EP7: 0.041576 | EQ7: 0.0322 | ER7: 0.034934 | ES7: -0.02792 | ET7: 0.065997 | EU7: 0.014204 | EV7: -0.018209 | EW7: 0.006657 | EX7: 0.045963 | EY7: -0.066784 | EZ7: 0.054171 | FA7: -0.069202 | FB7: 0.042942 | FC7: -0.005519 | FD7: 0.015904 | FE7: -0.053487 | FF7: 0.071358 | FG7: 0.005373 | FH7: 0.001698 | FI7: 0.010095 | FJ7: -0.022698 | FK7: -0.036976 | FL7: -0.052086 | FM7: -0.066209 | FN7: 0.061982 | FO7: 0.031808 | FP7: -0.056919 | FQ7: -0.071494 | FR7: 0.01819 | FS7: 0.120043 | FT7: 0.046792 | FU7: 0.007433 | FV7: -0.009751 | FW7: 0.045997 | FX7: 0.027097 | FY7: 0.016254 | FZ7: -0.028065 | GA7: 0.135358 | GB7: 0.023606 | GC7: -0.001285
B8: =Deals!B8 -> Worthington Enterprises, Inc. | C8: 1 | D8: -0.08365 | E8: 0.136929 | F8: -0.069864 | G8: -0.089126 | H8: 0.259692 | I8: 0.060088 | J8: -0.036866 | K8: 0.036364 | L8: -0.001847 | M8: 0.089732 | N8: 0.103141 | O8: 0.05733 | P8: 0.031295 | Q8: 0.093155 | R8: 0.038735 | S8: 0.068365 | T8: -0.077661 | U8: 0.128035 | V8: -0.068214 | W8: 0.033003 | X8: 0.177462 | Y8: 0.029107 | Z8: 0.008629 | AA8: -0.036597 | AB8: -0.016774 | AC8: -0.040391 | AD8: -0.037908 | AE8: 0.095109 | AF8: 0.06799 | AG8: -0.111292 | AH8: 0.057255 | AI8: -0.079624 | AJ8: 0.03842 | AK8: -0.024321 | AL8: -0.202068 | AM8: -0.005317 | AN8: -0.097895 | AO8: -0.014444 | AP8: 0.015784 | AQ8: 0.006659 | AR8: 0.104741 | AS8: -0.0998 | AT8: -0.054324 | AU8: 0.034779 | AV8: 0.159366 | AW8: 0.00228 | AX8: -0.020474 | AY8: 0.01493 | AZ8: 0.016999 | BA8: 0.145612 | BB8: 0.059203 | BC8: -0.010331 | BD8: 0.132227 | BE8: 0.047518 | BF8: -0.031821 | BG8: 0.11958 | BH8: -0.021445 | BI8: 0.197447 | BJ8: -0.157072 | BK8: 0.007378 | BM8: 0.012292 | BN8: 0.027379 | BO8: -0.026073 | BP8: -0.076493 | BQ8: 0.038655 | BR8: -0.008013 | BS8: 0.028409 | BT8: 0.033264 | BU8: -0.012454 | BV8: 0.010914 | BW8: 0.030347 | BX8: 0.074979 | BY8: 0.00909 | BZ8: 0.039187 | CA8: -0.012214 | CB8: 0.056093 | CC8: -0.003673 | CD8: 0.06385 | CE8: -0.031632 | CF8: 0.075391 | CG8: 0.012683 | CH8: 0.03311 | CI8: 0.035485 | CJ8: -0.05261 | CK8: 0.060029 | CL8: 0.014743 | CM8: -0.030005 | CN8: 0.01466 | CO8: 0.057216 | CP8: -0.055099 | CQ8: 0.040594 | CR8: -0.053281 | CS8: 0.061126 | CT8: -0.004914 | CU8: 0.028335 | CV8: -0.043235 | CW8: 0.065447 | CX8: 0.008073 | CY8: -0.027893 | CZ8: 0.028258 | DA8: -0.002503 | DB8: -0.006629 | DC8: -0.034871 | DD8: -0.050823 | DE8: 0.063448 | DF8: 0.030003 | DG8: -0.050286 | DH8: -0.083393 | DI8: 0.018763 | DJ8: 0.08417 | DK8: -2.2e-05 | DL8: 0.00702 | DM8: -0.008668 | DN8: 0.05865 | DO8: 0.021658 | DP8: 0.009925 | DQ8: -0.056638 | DR8: 0.130835 | DS8: 0.024077 | DT8: -0.005274 | DV8: 0.011654 | DW8: 0.02661 | DX8: -0.031859 | DY8: -0.08365 | DZ8: 0.043386 | EA8: -0.011056 | EB8: 0.029146 | EC8: 0.03486 | ED8: -0.012993 | EE8: 0.012777 | EF8: 0.033761 | EG8: 0.07714 | EH8: 0.009752 | EI8: 0.03385 | EJ8: -0.004858 | EK8: 0.060055 | EL8: -0.001103 | EM8: 0.066793 | EN8: -0.03239 | EO8: 0.074048 | EP8: 0.016767 | EQ8: 0.034997 | ER8: 0.036564 | ES8: -0.048941 | ET8: 0.058335 | EU8: 0.018288 | EV8: -0.028006 | EW8: 0.014879 | EX8: 0.058355 | EY8: -0.055238 | EZ8: 0.042686 | FA8: -0.056324 | FB8: 0.060625 | FC8: -0.009011 | FD8: 0.029404 | FE8: -0.051372 | FF8: 0.073055 | FG8: 0.001979 | FH8: -0.012164 | FI8: 0.020936 | FJ8: 0.002798 | FK8: -0.009748 | FL8: -0.03247 | FM8: -0.05037 | FN8: 0.071433 | FO8: 0.034408 | FP8: -0.05314 | FQ8: -0.082202 | FR8: 0.022044 | FS8: 0.079691 | FT8: 0.017991 | FU8: 0.011739 | FV8: -0.014708 | FW8: 0.056092 | FX8: 0.019127 | FY8: 0.013815 | FZ8: -0.055074 | GA8: 0.135632 | GB8: 0.026419 | GC8: -0.00429
B9: =Deals!B9 -> Firstcash Holdings, Inc. | C9: 1 | D9: 0.049938 | E9: 0.014908 | F9: -0.044999 | G9: -0.085449 | H9: 0.072344 | I9: -0.001743 | J9: 0.112718 | K9: 0.031152 | L9: -0.029341 | M9: 0.081729 | N9: 0.027117 | O9: 0.074365 | P9: -0.007503 | Q9: 0.102627 | R9: -0.117758 | S9: 0.045463 | T9: -0.085486 | U9: 0.085145 | V9: 0.035019 | W9: 0.047404 | X9: 0.044913 | Y9: 0.050091 | Z9: -0.026448 | AA9: -0.205369 | AB9: 0.075092 | AC9: -0.044861 | AD9: -0.033492 | AE9: 0.076892 | AF9: 0.096535 | AG9: -0.02049 | AH9: 0.023932 | AI9: -0.030817 | AJ9: 0.055377 | AK9: -0.022004 | AL9: -0.036518 | AM9: -0.10688 | AN9: -0.031778 | AO9: -0.033652 | AP9: 0.039123 | AQ9: -0.036202 | AR9: -0.021464 | AS9: -0.107918 | AT9: 0.014753 | AU9: -0.029319 | AV9: -0.047678 | AW9: 0.019397 | AX9: -0.037542 | AY9: -0.051563 | AZ9: 0.191408 | BA9: 0.092246 | BB9: -0.007165 | BC9: -0.041876 | BD9: 0.174868 | BE9: -0.00039 | BF9: 0.010427 | BG9: -0.089714 | BH9: 0.002549 | BI9: -0.023517 | BJ9: 0.023965 | BK9: -0.091489 | BM9: 0.044547 | BN9: 0.018867 | BO9: 0.000317 | BP9: -0.053893 | BQ9: 0.069423 | BR9: -0.038722 | BS9: 0.018064 | BT9: 0.049843 | BU9: -0.055653 | BV9: -0.004674 | BW9: 0.035149 | BX9: 0.070883 | BY9: 0.008534 | BZ9: 0.05133 | CA9: -0.007138 | CB9: 0.054283 | CC9: 0.018013 | CD9: 0.070419 | CE9: -0.005681 | CF9: 0.068252 | CG9: 0.006633 | CH9: 0.064781 | CI9: 0.028395 | CJ9: 0.001207 | CK9: 0.048235 | CL9: -0.041372 | CM9: -0.067967 | CN9: -0.004401 | CO9: 0.07526 | CP9: -0.050242 | CQ9: 0.055697 | CR9: -0.049962 | CS9: 0.083606 | CT9: 0.016146 | CU9: 0.009829 | CV9: -0.012307 | CW9: 0.074649 | CX9: 0.03186 | CY9: -0.039124 | CZ9: 0.028908 | DA9: 0.012554 | DB9: -0.001721 | DC9: -0.100334 | DD9: -0.095752 | DE9: 0.03069 | DF9: 0.080711 | DG9: -0.03045 | DH9: -0.17716 | DI9: -0.014349 | DJ9: 0.08568 | DK9: 0.045734 | DL9: 0.033855 | DM9: -0.003661 | DN9: 0.0807 | DO9: 0.003679 | DP9: 0.049663 | DQ9: -0.099241 | DR9: 0.093107 | DS9: -0.022398 | DT9: 0.025391 | DV9: 0.040077 | DW9: 0.014133 | DX9: -0.006743 | DY9: -0.060207 | DZ9: 0.065607 | EA9: -0.040728 | EB9: 0.026895 | EC9: 0.051158 | ED9: -0.057903 | EE9: -0.004906 | EF9: 0.035724 | EG9: 0.068896 | EH9: 0.007246 | EI9: 0.049268 | EJ9: -0.006341 | EK9: 0.062929 | EL9: 0.01317 | EM9: 0.075285 | EN9: -0.011026 | EO9: 0.06595 | EP9: 0.010795 | EQ9: 0.066441 | ER9: 0.026067 | ES9: 0.009733 | ET9: 0.03455 | EU9: -0.025746 | EV9: -0.061748 | EW9: -0.008859 | EX9: 0.08789 | EY9: -0.063573 | EZ9: 0.054443 | FA9: -0.0538 | FB9: 0.082902 | FC9: 0.013356 | FD9: 0.011862 | FE9: -0.025271 | FF9: 0.093297 | FG9: 0.030284 | FH9: -0.02015 | FI9: 0.00991 | FJ9: 0.017252 | FK9: -0.003168 | FL9: -0.092336 | FM9: -0.102882 | FN9: 0.04163 | FO9: 0.086308 | FP9: -0.033729 | FQ9: -0.1895 | FR9: -0.00396 | FS9: 0.102724 | FT9: 0.056026 | FU9: 0.03106 | FV9: -0.008278 | FW9: 0.083394 | FX9: -0.000451 | FY9: 0.049994 | FZ9: -0.091743 | GA9: 0.084524 | GB9: -0.015069 | GC9: 0.021881
B10: =Deals!B10 -> Gilead Sciences, Inc. | C10: 1 | D10: -0.068052 | E10: 0.073021 | F10: 0.064675 | G10: -0.039792 | H10: 0.026627 | I10: 0.059477 | J10: 0.061844 | K10: 0.149766 | L10: 0.012739 | M10: 0.116487 | N10: -0.020667 | O10: 0.0742 | P10: 0.08289 | Q10: 0.145599 | R10: 0.034736 | S10: 0.075829 | T10: -0.058921 | U10: 0.197581 | V10: -0.018404 | W10: 0.043139 | X10: 0.132098 | Y10: 0.048542 | Z10: 0.006298 | AA10: 0.073901 | AB10: 0.026534 | AC10: -0.1441 | AD10: 0.107677 | AE10: 0.034654 | AF10: 0.020933 | AG10: 0.104209 | AH10: 0.174877 | AI10: -0.01032 | AJ10: 0.052137 | AK10: -0.104286 | AL10: -0.060407 | AM10: 0.112137 | AN10: -0.012401 | AO10: -0.052159 | AP10: 0.024254 | AQ10: 0.117003 | AR10: 0.042843 | AS10: 0.006662 | AT10: -0.108519 | AU10: -0.06548 | AV10: 0.101232 | AW10: -0.020068 | AX10: -0.045017 | AY10: -0.179761 | AZ10: 0.051205 | BA10: 0.052837 | BB10: -0.039734 | BC10: -0.013037 | BD10: -0.04181 | BE10: -0.047351 | BF10: -0.013716 | BG10: 0.009441 | BH10: -0.069388 | BI10: 0.000951 | BJ10: -0.028358 | BK10: 0.01173 | BM10: 0.051896 | BN10: 0.040349 | BO10: 0.000173 | BP10: -0.063942 | BQ10: 0.028124 | BR10: 0.013732 | BS10: 0.020822 | BT10: 0.017873 | BU10: -0.033013 | BV10: 0.01218 | BW10: -0.009557 | BX10: 0.036126 | BY10: 0.011784 | BZ10: 0.039569 | CA10: 0.02303 | CB10: 0.012043 | CC10: -0.023098 | CD10: 0.059978 | CE10: -0.014845 | CF10: 0.043089 | CG10: 0.048861 | CH10: 0.031878 | CI10: 0.02593 | CJ10: -0.040348 | CK10: 0.051051 | CL10: -0.014273 | CM10: 0.015398 | CN10: 0.031845 | CO10: 0.011359 | CP10: -0.016618 | CQ10: 0.048826 | CR10: -0.006074 | CS10: 0.02283 | CT10: 0.035515 | CU10: -0.012368 | CV10: -0.008353 | CW10: 0.059661 | CX10: -0.010453 | CY10: 0.002214 | CZ10: 0.015755 | DA10: -0.004802 | DB10: 0.031311 | DC10: -0.059184 | DD10: -0.017 | DE10: 0.085501 | DF10: 0.000862 | DG10: -0.013923 | DH10: -0.060194 | DI10: 0.002648 | DJ10: 0.065164 | DK10: -0.007147 | DL10: 0.016604 | DM10: 0.000702 | DN10: 0.051821 | DO10: -0.007159 | DP10: 0.005453 | DQ10: -0.023749 | DR10: 0.010556 | DS10: 0.012329 | DT10: 0.034037 | DV10: 0.038624 | DW10: 0.026205 | DX10: 0.000215 | DY10: -0.076207 | DZ10: 0.026946 | EA10: -1.6e-05 | EB10: 0.025875 | EC10: 0.02156 | ED10: -0.02846 | EE10: 0.022282 | EF10: 0.014411 | EG10: 0.054591 | EH10: 0.013843 | EI10: 0.045019 | EJ10: 0.015903 | EK10: 0.016297 | EL10: -0.012769 | EM10: 0.061764 | EN10: -0.019309 | EO10: 0.050029 | EP10: 0.036587 | EQ10: 0.022659 | ER10: 0.026889 | ES10: -0.025893 | ET10: 0.05659 | EU10: -0.015759 | EV10: 0.002797 | EW10: 0.028851 | EX10: 0.014915 | EY10: -0.024557 | EZ10: 0.050111 | FA10: -0.013994 | FB10: 0.02638 | FC10: 0.037801 | FD10: -0.009339 | FE10: -0.020233 | FF10: 0.068639 | FG10: -0.006734 | FH10: 0.006928 | FI10: 0.003641 | FJ10: -0.010359 | FK10: 0.028827 | FL10: -0.064724 | FM10: -0.022601 | FN10: 0.075987 | FO10: 0.001824 | FP10: -0.00837 | FQ10: -0.063947 | FR10: 0.012902 | FS10: 0.060117 | FT10: -0.004977 | FU10: 0.008057 | FV10: 0.006806 | FW10: 0.049935 | FX10: -0.009553 | FY10: -0.002709 | FZ10: -0.034978 | GA10: 0.024645 | GB10: -0.000502 | GC10: 0.034016
B11: =Deals!B11 -> 3D Systems Corp | C11: 1 | D11: 0.171548 | E11: 0.050893 | F11: 0.252761 | G11: 0.030858 | H11: 0.123026 | I11: 0.113064 | J11: 0.150263 | K11: -0.248456 | L11: 0.324201 | M11: 0.027816 | N11: 0.193245 | O11: 0.084349 | P11: -0.361106 | Q11: -0.127706 | R11: 0.186104 | S11: 0.268828 | T11: -0.095218 | U11: 0.075854 | V11: 0.088291 | W11: 0.050389 | X11: 0.152806 | Y11: 0.20196 | Z11: 0.242214 | AA11: -0.163564 | AB11: -0.022771 | AC11: -0.221301 | AD11: -0.199662 | AE11: 0.06992 | AF11: 0.180652 | AG11: -0.161706 | AH11: 0.067425 | AI11: -0.133433 | AJ11: -0.184818 | AK11: -0.066667 | AL11: -0.068311 | AM11: -0.115303 | AN11: 0.047799 | AO11: -0.100098 | AP11: -0.084974 | AQ11: -0.128338 | AR11: -0.107453 | AS11: -0.32582 | AT11: 0.043313 | AU11: -0.158776 | AV11: -0.129004 | AW11: -0.093439 | AX11: -0.047149 | AY11: -0.078251 | AZ11: 0.332085 | BA11: 0.449859 | BB11: 0.143504 | BC11: -0.243075 | BD11: 0.022405 | BE11: -0.021914 | BF11: 0.082898 | BG11: 0.237931 | BH11: -0.227298 | BI11: -0.001442 | BJ11: -0.040433 | BK11: 0.240783 | BM11: 0.044547 | BN11: 0.018867 | BO11: 0.000317 | BP11: -0.053893 | BQ11: 0.069423 | BR11: -0.038722 | BS11: 0.018064 | BT11: 0.049843 | BU11: -0.055653 | BV11: -0.004674 | BW11: 0.035149 | BX11: 0.070883 | BY11: 0.008534 | BZ11: 0.05133 | CA11: -0.007138 | CB11: 0.054283 | CC11: 0.018013 | CD11: 0.070419 | CE11: -0.005681 | CF11: 0.068252 | CG11: 0.006633 | CH11: 0.064781 | CI11: 0.028395 | CJ11: 0.001207 | CK11: 0.048235 | CL11: -0.041372 | CM11: -0.067967 | CN11: -0.004401 | CO11: 0.07526 | CP11: -0.050242 | CQ11: 0.055697 | CR11: -0.049962 | CS11: 0.083606 | CT11: 0.016146 | CU11: 0.009829 | CV11: -0.012307 | CW11: 0.074649 | CX11: 0.03186 | CY11: -0.039124 | CZ11: 0.028908 | DA11: 0.012554 | DB11: -0.001721 | DC11: -0.100334 | DD11: -0.095752 | DE11: 0.03069 | DF11: 0.080711 | DG11: -0.03045 | DH11: -0.17716 | DI11: -0.014349 | DJ11: 0.08568 | DK11: 0.045734 | DL11: 0.033855 | DM11: -0.003661 | DN11: 0.0807 | DO11: 0.003679 | DP11: 0.049663 | DQ11: -0.099241 | DR11: 0.093107 | DS11: -0.022398 | DT11: 0.025391 | DV11: 0.040077 | DW11: 0.014133 | DX11: -0.006743 | DY11: -0.060207 | DZ11: 0.065607 | EA11: -0.040728 | EB11: 0.026895 | EC11: 0.051158 | ED11: -0.057903 | EE11: -0.004906 | EF11: 0.035724 | EG11: 0.068896 | EH11: 0.007246 | EI11: 0.049268 | EJ11: -0.006341 | EK11: 0.062929 | EL11: 0.01317 | EM11: 0.075285 | EN11: -0.011026 | EO11: 0.06595 | EP11: 0.010795 | EQ11: 0.066441 | ER11: 0.026067 | ES11: 0.009733 | ET11: 0.03455 | EU11: -0.025746 | EV11: -0.061748 | EW11: -0.008859 | EX11: 0.08789 | EY11: -0.063573 | EZ11: 0.054443 | FA11: -0.0538 | FB11: 0.082902 | FC11: 0.013356 | FD11: 0.011862 | FE11: -0.025271 | FF11: 0.093297 | FG11: 0.030284 | FH11: -0.02015 | FI11: 0.00991 | FJ11: 0.017252 | FK11: -0.003168 | FL11: -0.092336 | FM11: -0.102882 | FN11: 0.04163 | FO11: 0.086308 | FP11: -0.033729 | FQ11: -0.1895 | FR11: -0.00396 | FS11: 0.102724 | FT11: 0.056026 | FU11: 0.03106 | FV11: -0.008278 | FW11: 0.083394 | FX11: -0.000451 | FY11: 0.049994 | FZ11: -0.091743 | GA11: 0.084524 | GB11: -0.015069 | GC11: 0.021881
B12: =Deals!B12 -> Genesis Energy Lp | C12: 1 | D12: 0.099609 | E12: -0.0055 | F12: 0.021796 | G12: -0.070736 | H12: 0.010428 | I12: 0.067423 | J12: 0.057246 | K12: 0.040532 | L12: -0.027594 | M12: 0.112938 | N12: -0.004182 | O12: 0.141517 | P12: 0.140482 | Q12: 0.049402 | R12: 0.007196 | S12: 0.04327 | T12: 0.0335 | U12: -0.028362 | V12: -0.023671 | W12: 0.028765 | X12: 0.028201 | Y12: 0.010204 | Z12: 0.021173 | AA12: 0.056972 | AB12: -0.000545 | AC12: -0.014545 | AD12: 0.032657 | AE12: 0.02851 | AF12: -0.016842 | AG12: -0.053266 | AH12: 0.061155 | AI12: -0.054937 | AJ12: -0.077508 | AK12: -0.082326 | AL12: -0.036566 | AM12: 0.035479 | AN12: 0.06162 | AO12: 0.021739 | AP12: 0.070638 | AQ12: -0.021726 | AR12: -0.097471 | AS12: 0.025632 | AT12: -0.016445 | AU12: -0.121851 | AV12: 0.068075 | AW12: -0.023815 | AX12: -0.066328 | AY12: -0.208628 | AZ12: -0.098874 | BA12: 0.241312 | BB12: 0.040988 | BC12: 0.161937 | BD12: 0.018582 | BE12: -0.033881 | BF12: -0.016218 | BG12: 0.060911 | BH12: -0.061628 | BI12: 0.000286 | BJ12: 0.03091 | BK12: 0.013463 | BM12: 0.03564 | BN12: 0.016925 | BO12: -0.013647 | BP12: -0.079972 | BQ12: 0.018963 | BR12: -0.013357 | BS12: 0.046121 | BT12: 0.015771 | BU12: -0.004359 | BV12: 0.025113 | BW12: 0.023897 | BX12: 0.062127 | BY12: 0.00487 | BZ12: 0.052829 | CA12: -0.007109 | CB12: 0.041347 | CC12: -0.015247 | CD12: 0.057981 | CE12: -0.034983 | CF12: 0.058569 | CG12: 0.037265 | CH12: 0.037207 | CI12: 0.029865 | CJ12: -0.041643 | CK12: 0.045552 | CL12: 0.00605 | CM12: -0.020868 | CN12: 0.025203 | CO12: 0.037615 | CP12: -0.060663 | CQ12: 0.044977 | CR12: -0.04827 | CS12: 0.039518 | CT12: -0.003724 | CU12: 0.005191 | CV12: -0.038677 | CW12: 0.085639 | CX12: 0.017149 | CY12: -0.009998 | CZ12: 0.029717 | DA12: -0.011516 | DB12: -0.033357 | DC12: -0.035791 | DD12: -0.051436 | DE12: 0.074104 | DF12: 0.007963 | DG12: -0.046804 | DH12: -0.068914 | DI12: 0.023766 | DJ12: 0.078786 | DK12: 0.016005 | DL12: 0.006008 | DM12: -0.000795 | DN12: 0.065576 | DO12: 0.037891 | DP12: 0.003862 | DQ12: -0.029525 | DR12: 0.103264 | DS12: 0.015927 | DT12: 0.013463 | DV12: 0.035691 | DW12: 0.01669 | DX12: -0.019771 | DY12: -0.085092 | DZ12: 0.015011 | EA12: -0.013916 | EB12: 0.047372 | EC12: 0.020104 | ED12: -0.003816 | EE12: 0.025116 | EF12: 0.029117 | EG12: 0.05969 | EH12: 0.004146 | EI12: 0.052415 | EJ12: -0.011178 | EK12: 0.046099 | EL12: -0.015341 | EM12: 0.058453 | EN12: -0.037328 | EO12: 0.056178 | EP12: 0.039877 | EQ12: 0.037221 | ER12: 0.032848 | ES12: -0.043165 | ET12: 0.042305 | EU12: 0.008794 | EV12: -0.020111 | EW12: 0.026815 | EX12: 0.037007 | EY12: -0.062591 | EZ12: 0.046414 | FA12: -0.048632 | FB12: 0.043708 | FC12: -0.008139 | FD12: 0.001292 | FE12: -0.042807 | FF12: 0.086461 | FG12: 0.010184 | FH12: 0.003168 | FI12: 0.021695 | FJ12: -0.012441 | FK12: -0.032816 | FL12: -0.035298 | FM12: -0.052597 | FN12: 0.081152 | FO12: 0.0063 | FP12: -0.040284 | FQ12: -0.078335 | FR12: 0.026229 | FS12: 0.083064 | FT12: 0.026946 | FU12: 0.000891 | FV12: -0.001501 | FW12: 0.065978 | FX12: 0.037025 | FY12: 0.003486 | FZ12: -0.033383 | GA12: 0.109108 | GB12: 0.012881 | GC12: 0.010399
B13: =Deals!B13 -> ICF International, Inc. | C13: 1 | D13: -0.085039 | E13: -0.021597 | F13: -0.016949 | G13: -0.097835 | H13: 0.059556 | I13: 0.030621 | J13: -0.102971 | K13: -0.088022 | L13: -0.087065 | M13: 0.178202 | N13: 0.084181 | O13: -0.023464 | P13: 0.080821 | Q13: 0.099434 | R13: -0.003309 | S13: 0.112136 | T13: 0.045108 | U13: 0.059664 | V13: -0.014975 | W13: 0.076619 | X13: -0.02231 | Y13: 0.033507 | Z13: -0.029905 | AA13: -0.030251 | AB13: 0.200832 | AC13: -0.015092 | AD13: -0.0211 | AE13: -0.04542 | AF13: -0.049462 | AG13: -0.022342 | AH13: -0.022852 | AI13: -0.088514 | AJ13: 0.180253 | AK13: 0.067144 | AL13: 0.05673 | AM13: -0.088336 | AN13: 0.12152 | AO13: -0.02506 | AP13: -0.057528 | AQ13: -0.070649 | AR13: -0.025713 | AS13: 0.051635 | AT13: -0.06683 | AU13: -0.111663 | AV13: 0.009214 | AW13: 0.161722 | AX13: -0.001965 | AY13: -0.037964 | AZ13: -0.012569 | BA13: 0.017466 | BB13: 0.145476 | BC13: 0.035814 | BD13: 0.002943 | BE13: 0.011736 | BF13: 0.011358 | BG13: 0.05902 | BH13: 0.046931 | BI13: 0.192888 | BJ13: -0.00271 | BK13: -0.057971 | BM13: 0.009861 | BN13: 0.034662 | BO13: -0.013323 | BP13: -0.080339 | BQ13: 0.054737 | BR13: -0.017732 | BS13: 0.027338 | BT13: 0.046007 | BU13: -0.032182 | BV13: -0.001937 | BW13: 0.045318 | BX13: 0.056109 | BY13: 0.017514 | BZ13: 0.041721 | CA13: -0.007784 | CB13: 0.065535 | CC13: 0.010997 | CD13: 0.089501 | CE13: -0.037353 | CF13: 0.069327 | CG13: 0.040429 | CH13: 0.071859 | CI13: 0.012559 | CJ13: -0.03596 | CK13: 0.058009 | CL13: 0.008661 | CM13: -0.033099 | CN13: -0.00585 | CO13: 0.041741 | CP13: -0.04321 | CQ13: 0.044624 | CR13: -0.0578 | CS13: 0.072509 | CT13: -0.012612 | CU13: 0.043534 | CV13: -0.05091 | CW13: 0.051146 | CX13: 0.018305 | CY13: -0.020565 | CZ13: -0.001646 | DA13: 0.022 | DB13: -0.055373 | DC13: -0.035985 | DD13: -0.039847 | DE13: 0.05297 | DF13: 0.030741 | DG13: -0.052302 | DH13: -0.063009 | DI13: -0.01309 | DJ13: 0.068055 | DK13: 0.016072 | DL13: -0.008157 | DM13: 0.007352 | DN13: 0.048882 | DO13: 0.041045 | DP13: 0.030226 | DQ13: -0.035925 | DR13: 0.13831 | DS13: 0.080139 | DT13: -0.018857 | DV13: 0.024759 | DW13: 0.042259 | DX13: 0.000228 | DY13: -0.084832 | DZ13: 0.044137 | EA13: -0.015945 | EB13: 0.0255 | EC13: 0.043556 | ED13: -0.022199 | EE13: -0.009866 | EF13: 0.03416 | EG13: 0.06724 | EH13: 0.012135 | EI13: 0.040628 | EJ13: 0.0045 | EK13: 0.051579 | EL13: 0.011459 | EM13: 0.079555 | EN13: -0.029153 | EO13: 0.068792 | EP13: 0.047151 | EQ13: 0.065449 | ER13: 0.015166 | ES13: -0.006881 | ET13: 0.035091 | EU13: -0.000653 | EV13: -0.038076 | EW13: -0.003217 | EX13: 0.033817 | EY13: -0.039386 | EZ13: 0.035353 | FA13: -0.044869 | FB13: 0.03704 | FC13: -0.006985 | FD13: 0.041462 | FE13: -0.039313 | FF13: 0.048343 | FG13: 0.008998 | FH13: -0.01209 | FI13: 0.003564 | FJ13: 0.001854 | FK13: -0.050328 | FL13: -0.034308 | FM13: -0.049615 | FN13: 0.049806 | FO13: 0.011878 | FP13: -0.049649 | FQ13: -0.086043 | FR13: -0.014482 | FS13: 0.077828 | FT13: 0.037266 | FU13: -0.017486 | FV13: 0.008906 | FW13: 0.041202 | FX13: 0.034504 | FY13: 0.027047 | FZ13: -0.045937 | GA13: 0.097765 | GB13: 0.059961 | GC13: 0.000689
B14: =Deals!B14 -> Enovis CORP | C14: 1 | D14: 0.120553 | E14: 0.035861 | F14: -0.038309 | G14: -0.16406 | H14: -0.026827 | I14: 0.049692 | J14: 0.136489 | K14: 0.114929 | L14: -0.062176 | M14: 0.13376 | N14: 0.034881 | O14: 0.105576 | P14: -0.027124 | Q14: 0.07235 | R14: 0.002793 | S14: 0.069209 | T14: 0.044289 | U14: 0.018423 | V14: -0.018466 | W14: 0.084469 | X14: -0.009382 | Y14: 0.045926 | Z14: 0.08816 | AA14: -0.054012 | AB14: 0.180581 | AC14: 0.002812 | AD14: 0.009113 | AE14: 0.011253 | AF14: 0.024042 | AG14: -0.155219 | AH14: 0.010164 | AI14: -0.104386 | AJ14: -0.045463 | AK14: -0.052409 | AL14: 0.000776 | AM14: -0.121388 | AN14: 0.162657 | AO14: -0.093964 | AP14: 0.038969 | AQ14: 0.016132 | AR14: -0.084144 | AS14: -0.173564 | AT14: 0.017042 | AU14: -0.228925 | AV14: -0.098629 | AW14: 0.00408 | AX14: -0.137421 | AY14: -0.05182 | AZ14: 0.14318 | BA14: 0.129593 | BB14: 0.134313 | BC14: -0.164662 | BD14: -0.023256 | BE14: 0.109599 | BF14: 0.010899 | BG14: 0.058962 | BH14: 0.011454 | BI14: 0.183076 | BJ14: -0.044669 | BK14: 0.085444 | BM14: 0.044446 | BN14: 0.014495 | BO14: -0.021785 | BP14: -0.079095 | BQ14: 0.052776 | BR14: -0.026861 | BS14: 0.051294 | BT14: 0.028554 | BU14: -0.038571 | BV14: 0.028796 | BW14: 0.024315 | BX14: 0.054936 | BY14: 0.00502 | BZ14: 0.044964 | CA14: -0.020228 | CB14: 0.029833 | CC14: -0.004107 | CD14: 0.082928 | CE14: -0.016534 | CF14: 0.057374 | CG14: 0.033835 | CH14: 0.027704 | CI14: 0.016469 | CJ14: -0.003567 | CK14: 0.066358 | CL14: -0.046875 | CM14: -0.05681 | CN14: 0.012433 | CO14: 0.062082 | CP14: -0.054705 | CQ14: 0.063988 | CR14: -0.029935 | CS14: 0.058786 | CT14: 0.027658 | CU14: 0.017988 | CV14: -0.005831 | CW14: 0.073006 | CX14: 0.005411 | CY14: -0.031006 | CZ14: 0.044006 | DA14: 0.012921 | DB14: 0.019176 | DC14: -0.080326 | DD14: -0.060705 | DE14: 0.038969 | DF14: 0.019986 | DG14: -0.026704 | DH14: -0.116705 | DI14: -0.002874 | DJ14: 0.056488 | DK14: 0.011506 | DL14: 0.033278 | DM14: 0.008302 | DN14: 0.070227 | DO14: -0.01104 | DP14: 0 | DQ14: -0.048917 | DR14: 0.059159 | DS14: 0.003178 | DT14: 0.025215 | DV14: 0.04168 | DW14: 0.014419 | DX14: -0.027667 | DY14: -0.086416 | DZ14: 0.060592 | EA14: -0.033612 | EB14: 0.051174 | EC14: 0.025462 | ED14: -0.040985 | EE14: 0.032086 | EF14: 0.0249 | EG14: 0.050641 | EH14: 0.005701 | EI14: 0.039137 | EJ14: -0.015095 | EK14: 0.031393 | EL14: -0.008217 | EM14: 0.083009 | EN14: -0.014221 | EO14: 0.057053 | EP14: 0.036623 | EQ14: 0.042054 | ER14: 0.017674 | ES14: -0.010563 | ET14: 0.064953 | EU14: -0.033966 | EV14: -0.04956 | EW14: 0.009724 | EX14: 0.061219 | EY14: -0.054769 | EZ14: 0.059892 | FA14: -0.02737 | FB14: 0.061437 | FC14: 0.027518 | FD14: 0.018058 | FE14: -0.014795 | FF14: 0.082671 | FG14: 0.00508 | FH14: -0.029513 | FI14: 0.036794 | FJ14: 0.016471 | FK14: 0.01547 | FL14: -0.081561 | FM14: -0.066173 | FN14: 0.04778 | FO14: 0.032253 | FP14: -0.028193 | FQ14: -0.130111 | FR14: 0.001735 | FS14: 0.058941 | FT14: 0.017347 | FU14: 0.032947 | FV14: 0.007118 | FW14: 0.071002 | FX14: -0.012112 | FY14: -0.000608 | FZ14: -0.052504 | GA14: 0.057973 | GB14: -0.000793 | GC14: 0.027035
B15: =Deals!B15 -> International Paper Co /New/ | C15: 1 | D15: -0.001422 | E15: -0.050997 | F15: -0.1156 | G15: -0.009932 | H15: 0.134901 | I15: 0.061243 | J15: 0.050926 | K15: -0.013491 | L15: 0.044819 | M15: 0.072698 | N15: 0.039659 | O15: 0.069673 | P15: 0.058396 | Q15: 0.008587 | R15: -0.01137 | S15: -0.03987 | T15: 0.090273 | U15: -0.016645 | V15: -0.051049 | W15: -0.004241 | X15: 0.05526 | Y15: 0.049219 | Z15: -0.02631 | AA15: 0.031319 | AB15: -0.061567 | AC15: 0.016783 | AD15: 0.028407 | AE15: 0.059626 | AF15: -0.058847 | AG15: 0.027368 | AH15: -0.014654 | AI15: 0.060327 | AJ15: 0.071118 | AK15: -0.004459 | AL15: -0.017171 | AM15: 0.078807 | AN15: -0.016309 | AO15: -0.031898 | AP15: -0.027736 | AQ15: -0.081806 | AR15: 0.005884 | AS15: -0.090453 | AT15: -0.124015 | AU15: 0.129664 | AV15: -0.009838 | AW15: -0.098733 | AX15: -0.092573 | AY15: 0.056416 | AZ15: 0.14958 | BA15: 0.054337 | BB15: -0.015484 | BC15: 0.005218 | BD15: 0.080934 | BE15: 0.068107 | BF15: -0.010518 | BG15: -0.061484 | BH15: 0.092227 | BI15: 0.08908 | BJ15: 0.066717 | BK15: -0.060724 | BM15: 0.011104 | BN15: -0.006957 | BO15: -0.053137 | BP15: 0.054172 | BQ15: 0.01408 | BR15: 0.015463 | BS15: 0.035857 | BT15: -0.02592 | BU15: -0.001378 | BV15: 0.015409 | BW15: 0.056 | BX15: 0.019792 | BY15: 0.036318 | BZ15: 0.018478 | CA15: 0.013823 | CB15: 0.001531 | CC15: 0.046444 | CD15: -0.035744 | CE15: 0.025945 | CF15: 0.054352 | CG15: 0.016052 | CH15: 0.035924 | CI15: -0.035102 | CJ15: 0.029857 | CK15: 0.022111 | CL15: 0.014137 | CM15: 0.023498 | CN15: 0.02564 | CO15: -0.004222 | CP15: 0.022102 | CQ15: -0.016297 | CR15: 0.019633 | CS15: 0.033343 | CT15: -0.001868 | CU15: -0.041801 | CV15: 0.067385 | CW15: -0.02256 | CX15: 0.013814 | CY15: 0.011985 | CZ15: -0.016933 | DA15: 0.001147 | DB15: -0.056437 | DC15: -0.018387 | DD15: 0.085874 | DE15: -0.005096 | DF15: -0.022773 | DG15: -0.041199 | DH15: 0.013535 | DI15: 0.065163 | DJ15: 0.025925 | DK15: 0.021844 | DL15: 0.024846 | DM15: 0.01713 | DN15: -0.001476 | DO15: 0.008286 | DP15: -0.021076 | DQ15: 0.046286 | DR15: 0.022528 | DS15: -0.005353 | DT15: 0.023452 | DV15: 0.00889 | DW15: -0.005731 | DX15: -0.065057 | DY15: 0.035797 | DZ15: 0.007011 | EA15: 0.032033 | EB15: 0.024719 | EC15: -0.004593 | ED15: 0.006014 | EE15: 0.02747 | EF15: 0.065184 | EG15: 0.018151 | EH15: 0.051292 | EI15: 0.02256 | EJ15: 0.019439 | EK15: 0.004793 | EL15: 0.049384 | EM15: -0.027341 | EN15: 0.028478 | EO15: 0.047864 | EP15: 0.018236 | EQ15: 0.030343 | ER15: -0.025246 | ES15: 0.045547 | ET15: 0.016672 | EU15: 0.012388 | EV15: 0.018194 | EW15: 0.029903 | EX15: -0.007776 | EY15: 0.030607 | EZ15: -0.015773 | FA15: 0.019988 | FB15: 0.033075 | FC15: -0.002345 | FD15: -0.04333 | FE15: 0.071223 | FF15: -0.015691 | FG15: 0.009233 | FH15: 0.003747 | FI15: -0.021108 | FJ15: 0.002598 | FK15: -0.05208 | FL15: -0.026202 | FM15: 0.076828 | FN15: -0.00011 | FO15: -0.034144 | FP15: -0.039422 | FQ15: -0.002125 | FR15: 0.084992 | FS15: 0.028284 | FT15: 0.02136 | FU15: 0.007837 | FV15: 0.032734 | FW15: 0.004087 | FX15: 0.011858 | FY15: -0.01357 | FZ15: 0.066072 | GA15: 0.010798 | GB15: 0.018176 | GC15: 0.02874
B16: =Deals!B16 -> Synopsys, Inc | C16: 1 | D16: 0.006236 | E16: -0.0212 | F16: -0.015328 | G16: -0.004061 | H16: 0.029222 | I16: 0.090459 | J16: -0.00106 | K16: -0.024095 | L16: 0.020497 | M16: -0.031181 | N16: 0.050403 | O16: 0.047548 | P16: 0.024265 | Q16: -0.00864 | R16: 0.024459 | S16: -0.018935 | T16: 0.036084 | U16: -0.021058 | V16: 0.039713 | W16: -0.033952 | X16: 0.009336 | Y16: 0.103645 | Z16: -0.017501 | AA16: 0.013547 | AB16: -0.049257 | AC16: -0.020568 | AD16: 0.023126 | AE16: 0.008574 | AF16: -0.027048 | AG16: 0.08287 | AH16: -0.029462 | AI16: 0.032372 | AJ16: 0.058809 | AK16: 0.001844 | AL16: -0.011042 | AM16: 0.079553 | AN16: -0.001939 | AO16: 0.01209 | AP16: 0.064206 | AQ16: 0.015234 | AR16: 0.003751 | AS16: -0.076908 | AT16: -0.015981 | AU16: 0.082287 | AV16: 0.002001 | AW16: -0.089257 | AX16: -0.059417 | AY16: 0.043124 | AZ16: 0.082458 | BA16: -0.018993 | BB16: 0.087332 | BC16: 0.046642 | BD16: 0.001479 | BE16: 0.094719 | BF16: 0.001012 | BG16: -0.000674 | BH16: 0.019727 | BI16: -0.026786 | BJ16: 0.068468 | BK16: 0.135952 | BM16: 0.006311 | BN16: -0.005028 | BO16: -0.088132 | BP16: 0.039208 | BQ16: 0.004596 | BR16: 0.025858 | BS16: 0.024552 | BT16: -0.005801 | BU16: -0.000505 | BV16: 0.028551 | BW16: 0.066681 | BX16: 0.016982 | BY16: 0.042198 | BZ16: -0.006672 | CA16: 0.015315 | CB16: -0.012367 | CC16: 0.065184 | CD16: -0.031385 | CE16: 0.051904 | CF16: 0.02806 | CG16: 0.008498 | CH16: 0.028176 | CI16: -0.008152 | CJ16: 0.048088 | CK16: 0.00209 | CL16: 0.001289 | CM16: 0.033027 | CN16: 0.039543 | CO16: -0.033145 | CP16: 0.04848 | CQ16: -0.045069 | CR16: 0.038236 | CS16: 0.03348 | CT16: 0.003273 | CU16: -0.010601 | CV16: 0.075713 | CW16: 0.011038 | CX16: -0.00926 | CY16: 0.029853 | CZ16: -0.021078 | DA16: -0.00198 | DB16: -0.047488 | DC16: -0.043814 | DD16: 0.07451 | DE16: 0.009557 | DF16: -0.044603 | DG16: -0.064723 | DH16: 0.001069 | DI16: 0.095151 | DJ16: 0.018491 | DK16: 0.045514 | DL16: -0.012791 | DM16: 0.033162 | DN16: 0.021293 | DO16: 0.011081 | DP16: -0.008831 | DQ16: 0.072449 | DR16: 0.012484 | DS16: 0.015297 | DT16: 0.030587 | DV16: 0.011422 | DW16: -0.011434 | DX16: -0.090474 | DY16: 0.044112 | DZ16: 0.010579 | EA16: 0.033163 | EB16: 0.025597 | EC16: -0.004533 | ED16: 0.004397 | EE16: 0.029029 | EF16: 0.063545 | EG16: 0.023451 | EH16: 0.043648 | EI16: -0.005544 | EJ16: 0.02183 | EK16: -0.013395 | EL16: 0.062888 | EM16: -0.033477 | EN16: 0.060979 | EO16: 0.02917 | EP16: 0.010095 | EQ16: 0.029533 | ER16: -0.003427 | ES16: 0.045803 | ET16: -0.000132 | EU16: 0.002431 | EV16: 0.036902 | EW16: 0.040403 | EX16: -0.035133 | EY16: 0.045497 | EZ16: -0.044913 | FA16: 0.033794 | FB16: 0.028917 | FC16: -0.001018 | FD16: -0.022323 | FE16: 0.080976 | FF16: 0.007241 | FG16: -0.000627 | FH16: 0.018439 | FI16: -0.023752 | FJ16: 0.001638 | FK16: -0.053171 | FL16: -0.047451 | FM16: 0.064849 | FN16: 0.003787 | FO16: -0.048371 | FP16: -0.059277 | FQ16: 0.007081 | FR16: 0.101215 | FS16: 0.026988 | FT16: 0.032746 | FU16: -0.024517 | FV16: 0.033259 | FW16: 0.020056 | FX16: 0.010726 | FY16: -0.009775 | FZ16: 0.072883 | GA16: 0.017056 | GB16: 0.016222 | GC16: 0.027022
B17: =Deals!B17 -> Aci Worldwide, Inc. | C17: 1 | D17: 0.065908 | E17: -0.010181 | F17: -0.041897 | G17: 0.157633 | H17: -0.004524 | I17: -0.014315 | J17: -0.025818 | K17: -0.074775 | L17: 0.102558 | M17: 0.013454 | N17: 0.088121 | O17: -0.03639 | P17: 0.066579 | Q17: -0.037863 | R17: -0.010636 | S17: -0.000645 | T17: 0.018718 | U17: 0.027878 | V17: 0.110746 | W17: 0.019608 | X17: 0.173803 | Y17: 0.004637 | Z17: -0.067538 | AA17: -0.009569 | AB17: -0.013993 | AC17: -0.034465 | AD17: -0.049694 | AE17: 0.027987 | AF17: 0.006985 | AG17: 0.038954 | AH17: -0.036466 | AI17: 0.025586 | AJ17: 0.010915 | AK17: 0.037018 | AL17: -0.084284 | AM17: 0.074716 | AN17: 0.091184 | AO17: 0.06325 | AP17: 0.033869 | AQ17: 0.031919 | AR17: -0.03663 | AS17: -0.098859 | AT17: -0.009845 | AU17: 0.133996 | AV17: -0.017954 | AW17: -0.090136 | AX17: -0.163551 | AY17: 0.042458 | AZ17: 0.114148 | BA17: -0.03848 | BB17: 0.033517 | BC17: -0.055663 | BD17: 0.015377 | BE17: -0.03584 | BF17: 0.01466 | BG17: -0.065015 | BH17: 0.027042 | BI17: -0.024718 | BJ17: 0.068871 | BK17: 0.008763 | BM17: 0.018867 | BN17: 0.000317 | BO17: -0.053893 | BP17: 0.069423 | BQ17: -0.038722 | BR17: 0.018064 | BS17: 0.049843 | BT17: -0.055653 | BU17: -0.004674 | BV17: 0.035149 | BW17: 0.070883 | BX17: 0.008534 | BY17: 0.05133 | BZ17: -0.007138 | CA17: 0.054283 | CB17: 0.018013 | CC17: 0.070419 | CD17: -0.005681 | CE17: 0.068252 | CF17: 0.006633 | CG17: 0.064781 | CH17: 0.028395 | CI17: 0.001207 | CJ17: 0.048235 | CK17: -0.041372 | CL17: -0.067967 | CM17: -0.004401 | CN17: 0.07526 | CO17: -0.050242 | CP17: 0.055697 | CQ17: -0.049962 | CR17: 0.083606 | CS17: 0.016146 | CT17: 0.009829 | CU17: -0.012307 | CV17: 0.074649 | CW17: 0.03186 | CX17: -0.039124 | CY17: 0.028908 | CZ17: 0.012554 | DA17: -0.001721 | DB17: -0.100334 | DC17: -0.095752 | DD17: 0.03069 | DE17: 0.080711 | DF17: -0.03045 | DG17: -0.17716 | DH17: -0.014349 | DI17: 0.08568 | DJ17: 0.045734 | DK17: 0.033855 | DL17: -0.003661 | DM17: 0.0807 | DN17: 0.003679 | DO17: 0.049663 | DP17: -0.099241 | DQ17: 0.093107 | DR17: -0.022398 | DS17: 0.025391 | DT17: 0.058384 | DV17: 0.014133 | DW17: -0.006743 | DX17: -0.060207 | DY17: 0.065607 | DZ17: -0.040728 | EA17: 0.026895 | EB17: 0.051158 | EC17: -0.057903 | ED17: -0.004906 | EE17: 0.035724 | EF17: 0.068896 | EG17: 0.007246 | EH17: 0.049268 | EI17: -0.006341 | EJ17: 0.062929 | EK17: 0.01317 | EL17: 0.075285 | EM17: -0.011026 | EN17: 0.06595 | EO17: 0.010795 | EP17: 0.066441 | EQ17: 0.026067 | ER17: 0.009733 | ES17: 0.03455 | ET17: -0.025746 | EU17: -0.061748 | EV17: -0.008859 | EW17: 0.08789 | EX17: -0.063573 | EY17: 0.054443 | EZ17: -0.0538 | FA17: 0.082902 | FB17: 0.013356 | FC17: 0.011862 | FD17: -0.025271 | FE17: 0.093297 | FF17: 0.030284 | FG17: -0.02015 | FH17: 0.00991 | FI17: 0.017252 | FJ17: -0.003168 | FK17: -0.092336 | FL17: -0.102882 | FM17: 0.04163 | FN17: 0.086308 | FO17: -0.033729 | FP17: -0.1895 | FQ17: -0.00396 | FR17: 0.102724 | FS17: 0.056026 | FT17: 0.03106 | FU17: -0.008278 | FV17: 0.083394 | FW17: -0.000451 | FX17: 0.049994 | FY17: -0.091743 | FZ17: 0.084524 | GA17: -0.015069 | GB17: 0.021881 | GC17: 0.051798
B18: =Deals!B18 -> Jazz Pharmaceuticals plc | C18: 1 | D18: -0.076234 | E18: 0.052816 | F18: -0.153439 | G18: 0.041898 | H18: 0.067985 | I18: -0.053256 | J18: 0.25245 | K18: -0.059282 | L18: 0.004849 | M18: -0.011691 | N18: 0.058965 | O18: 0.031743 | P18: -0.039017 | Q18: 0.043642 | R18: 0.164867 | S18: 0.011181 | T18: 0.099345 | U18: 0.160565 | V18: 0.048808 | W18: -0.013374 | X18: 0.274521 | Y18: 0.094336 | Z18: 0.198325 | AA18: 0.001879 | AB18: -0.087301 | AC18: -0.027257 | AD18: 0.051594 | AE18: 0.036303 | AF18: -0.04952 | AG18: 0.165963 | AH18: -0.014486 | AI18: 0.05157 | AJ18: 0.048863 | AK18: -0.075442 | AL18: 0.034264 | AM18: 0.004429 | AN18: 0.015874 | AO18: 0.034203 | AP18: 0.003637 | AQ18: -0.018288 | AR18: 0.091838 | AS18: -0.121827 | AT18: -0.213304 | AU18: 0.033657 | AV18: 0.067818 | AW18: -0.041135 | AX18: -0.084092 | AY18: -0.055616 | AZ18: 0.073779 | BA18: 0.154347 | BB18: 0.005707 | BC18: -0.06763 | BD18: 0.06836 | BE18: -0.179771 | BF18: -0.018978 | BG18: -0.098864 | BH18: -0.053348 | BI18: 0.052108 | BJ18: 0.118224 | BK18: 0.087762 | BM18: 0.014495 | BN18: -0.021785 | BO18: -0.079095 | BP18: 0.052776 | BQ18: -0.026861 | BR18: 0.051294 | BS18: 0.028554 | BT18: -0.038571 | BU18: 0.028796 | BV18: 0.024315 | BW18: 0.054936 | BX18: 0.00502 | BY18: 0.044964 | BZ18: -0.020228 | CA18: 0.029833 | CB18: -0.004107 | CC18: 0.082928 | CD18: -0.016534 | CE18: 0.057374 | CF18: 0.033835 | CG18: 0.027704 | CH18: 0.016469 | CI18: -0.003567 | CJ18: 0.066358 | CK18: -0.046875 | CL18: -0.05681 | CM18: 0.012433 | CN18: 0.062082 | CO18: -0.054705 | CP18: 0.063988 | CQ18: -0.029935 | CR18: 0.058786 | CS18: 0.027658 | CT18: 0.017988 | CU18: -0.005831 | CV18: 0.073006 | CW18: 0.005411 | CX18: -0.031006 | CY18: 0.044006 | CZ18: 0.012921 | DA18: 0.019176 | DB18: -0.080326 | DC18: -0.060705 | DD18: 0.038969 | DE18: 0.019986 | DF18: -0.026704 | DG18: -0.116705 | DH18: -0.002874 | DI18: 0.056488 | DJ18: 0.011506 | DK18: 0.033278 | DL18: 0.008302 | DM18: 0.070227 | DN18: -0.01104 | DO18: 0 | DP18: -0.048917 | DQ18: 0.059159 | DR18: 0.003178 | DS18: 0.025215 | DT18: 0.039548 | DV18: 0.014419 | DW18: -0.027667 | DX18: -0.086416 | DY18: 0.060592 | DZ18: -0.033612 | EA18: 0.051174 | EB18: 0.025462 | EC18: -0.040985 | ED18: 0.032086 | EE18: 0.0249 | EF18: 0.050641 | EG18: 0.005701 | EH18: 0.039137 | EI18: -0.015095 | EJ18: 0.031393 | EK18: -0.008217 | EL18: 0.083009 | EM18: -0.014221 | EN18: 0.057053 | EO18: 0.036623 | EP18: 0.042054 | EQ18: 0.017674 | ER18: -0.010563 | ES18: 0.064953 | ET18: -0.033966 | EU18: -0.04956 | EV18: 0.009724 | EW18: 0.061219 | EX18: -0.054769 | EY18: 0.059892 | EZ18: -0.02737 | FA18: 0.061437 | FB18: 0.027518 | FC18: 0.018058 | FD18: -0.014795 | FE18: 0.082671 | FF18: 0.00508 | FG18: -0.029513 | FH18: 0.036794 | FI18: 0.016471 | FJ18: 0.01547 | FK18: -0.081561 | FL18: -0.066173 | FM18: 0.04778 | FN18: 0.032253 | FO18: -0.028193 | FP18: -0.130111 | FQ18: 0.001735 | FR18: 0.058941 | FS18: 0.017347 | FT18: 0.032947 | FU18: 0.007118 | FV18: 0.071002 | FW18: -0.012112 | FX18: -0.000608 | FY18: -0.052504 | FZ18: 0.057973 | GA18: -0.000793 | GB18: 0.027035 | GC18: 0.042605
... B650: =Deals!B650 -> Clarivate Plc | C650: 1 | D650: 0.10747 | E650: -0.003916 | F650: -0.024465 | G650: 0.238245 | H650: 0.064738 | I650: 0.052649 | J650: -0.10455 | K650: -0.011171 | L650: 0.082726 | M650: -0.025917 | N650: -0.213891 | O650: 0.16 | P650: 0.058355 | Q650: 0.075546 | R650: -0.083555 | S650: -0.171813 | T650: 0.104825 | U650: -0.130607 | V650: 0.070776 | W650: -0.004691 | X650: 0.007712 | Y650: -0.30017 | Z650: -0.089915 | AA650: 0.118825 | AB650: -0.064439 | AC650: -0.058036 | AD650: -0.061611 | AE650: 0.045455 | AF650: -0.194617 | AG650: -0.195373 | AH650: 0.100106 | AI650: -0.052275 | AJ650: -0.14811 | AK650: 0.333333 | AL650: -0.089029 | AM650: -0.07305 | AN650: -0.056443 | AO650: -0.119639 | AP650: 0.221795 | AQ650: -0.002099 | AR650: -0.218717 | AS650: -0.096904 | AT650: -0.04918 | AU650: 0.216301 | AV650: 0.193299 | AW650: -0.034557 | AX650: -0.196868 | AY650: 0.034819 | AZ650: -0.090175 | BA650: -0.156805 | BB650: -0.001754 | BC650: 0.184534 | BD650: 0.017804 | BE650: 0.034985 | BF650: -0.070423 | BG650: -0.131818 | BH650: -0.113438 | BI650: 0.066929 | BJ650: -0.208487 | BK650: -0.083916 | BM650: 0.165635 | BN650: 0.108631 | BO650: 0.022515 | BP650: 0.060034 | BQ650: 0.042064 | BR650: 0.00853 | BS650: 0.014059 | BT650: 0.135594 | BU650: 0.068794 | BV650: -0.002337 | BW650: 0.034689 | BX650: -0.020006 | BY650: 0.043697 | BZ650: -0.020314 | CA650: 0.05157 | CB650: -0.008614 | CC650: 0.031631 | CD650: -0.042971 | CE650: 0.047924 | CF650: -0.063866 | CG650: 0.003966 | CH650: -0.127141 | CI650: 0.001103 | CJ650: 0.001259 | CK650: -0.107022 | CL650: -0.028824 | CM650: -0.072625 | CN650: 0.130842 | CO650: -0.025181 | CP650: -0.091353 | CQ650: 0.057844 | CR650: 0.043218 | CS650: -0.053526 | CT650: 0.096917 | CU650: -0.024248 | CV650: 0.012549 | CW650: -0.018976 | CX650: 0.00158 | CY650: 0.08151 | CZ650: 0.012495 | DA650: -0.024647 | DB650: -0.058736 | DC650: -0.06088 | DD650: 0.098774 | DE650: 0.08847 | DF650: -0.016905 | DG650: 0.070309 | DH650: 0.038473 | DI650: -0.057327 | DJ650: 0.025533 | DK650: -0.006069 | DL650: 0.032133 | DM650: 0.017784 | DN650: 0.034516 | DO650: -0.010065 | DP650: 0.097341 | DQ650: -0.082651 | DR650: 0.042638 | DS650: -0.042825 | DT650: -0.066421 | DV650: 0.181242 | DW650: 0.100358 | DX650: 0.023159 | DY650: 0.053911 | DZ650: 0.040966 | EA650: 0.005233 | EB650: 0.019264 | EC650: 0.135549 | ED650: 0.067697 | EE650: 0.004164 | EF650: 0.031611 | EG650: -0.019813 | EH650: 0.037602 | EI650: -0.018649 | EJ650: 0.047074 | EK650: -0.012965 | EL650: 0.026925 | EM650: -0.043898 | EN650: 0.049157 | EO650: -0.074862 | EP650: 0.009118 | EQ650: -0.133336 | ER650: -0.004978 | ES650: 0.001746 | ET650: -0.124799 | EU650: -0.039308 | EV650: -0.070351 | EW650: 0.130499 | EX650: -0.023216 | EY650: -0.090202 | EZ650: 0.053736 | FA650: 0.048669 | FB650: -0.052265 | FC650: 0.117259 | FD650: -0.019842 | FE650: 0.012199 | FF650: -0.009812 | FG650: 0.008894 | FH650: 0.090874 | FI650: 0.014205 | FJ650: -0.019595 | FK650: -0.061965 | FL650: -0.063279 | FM650: 0.099242 | FN650: 0.096129 | FO650: -0.01973 | FP650: 0.076137 | FQ650: 0.039414 | FR650: -0.059407 | FS650: 0.019381 | FT650: -0.010354 | FU650: 0.033709 | FV650: 0.014427 | FW650: 0.029627 | FX650: -0.006623 | FY650: 0.091114 | FZ650: -0.075772 | GA650: 0.036599 | GB650: -0.045902 | GC650: -0.058795
B651: =Deals!B651 -> Danaher Corporation | C651: 1 | D651: 0.019271 | E651: 0.062421 | F651: 0.152519 | G651: 0.013101 | H651: 0.043784 | I651: 0.065992 | J651: -0.021391 | K651: -0.010284 | L651: 0.070676 | M651: -0.076396 | N651: 0.025584 | O651: 0.128221 | P651: 0.008663 | Q651: 0.048528 | R651: 0.108548 | S651: 0.08965 | T651: -0.060186 | U651: 0.024077 | V651: 0.031658 | W651: 0.023567 | X651: -0.131364 | Y651: -0.039819 | Z651: 0.069859 | AA651: -0.143865 | AB651: 0.050532 | AC651: -0.038094 | AD651: 0.149692 | AE651: -0.07397 | AF651: -0.042125 | AG651: -0.02563 | AH651: 0.086383 | AI651: -0.028309 | AJ651: -0.003918 | AK651: -0.063734 | AL651: 0.019311 | AM651: -0.06003 | AN651: -0.030771 | AO651: 0.046381 | AP651: 0.06275 | AQ651: 0.038971 | AR651: -0.063774 | AS651: -0.22495 | AT651: 0.162952 | AU651: 0.037034 | AV651: 0.037045 | AW651: 0.055146 | AX651: -0.012444 | AY651: -0.012414 | AZ651: 0.041278 | BA651: -0.026012 | BB651: 0.108985 | BC651: -0.028042 | BD651: 0.033344 | BE651: -0.116395 | BF651: -0.024302 | BG651: -0.041178 | BH651: -0.029667 | BI651: -0.067253 | BJ651: -0.011744 | BM651: 0.054962 | BN651: -0.008925 | BO651: 0.053871 | BP651: 0.063251 | BQ651: -0.033897 | BR651: 0.001671 | BS651: 0.095437 | BT651: 0.018008 | BU651: -0.004263 | BV651: 0.033434 | BW651: 0.050128 | BX651: 0.057761 | BY651: 0.008179 | BZ651: 0.014271 | CA651: 0.031948 | CB651: 0.041276 | CC651: -0.062381 | CD651: 0.056413 | CE651: -0.030068 | CF651: 0.052595 | CG651: -0.063404 | CH651: -0.043294 | CI651: 0.035373 | CJ651: -0.092215 | CK651: -0.003193 | CL651: -0.055016 | CM651: 0.054082 | CN651: -0.03048 | CO651: -0.053718 | CP651: 0.074071 | CQ651: 0.066348 | CR651: -0.037114 | CS651: 0.019238 | CT651: -0.021663 | CU651: 0.032915 | CV651: 0.01434 | CW651: -0.011454 | CX651: 0.054518 | CY651: 0.062584 | CZ651: -0.00811 | DA651: -0.043722 | DB651: -0.049086 | DC651: 0.069409 | DD651: 0.047821 | DE651: -0.005114 | DF651: 0.016618 | DG651: 0.064515 | DH651: 0.01242 | DI651: 0.040278 | DJ651: 0.01096 | DK651: 0.022329 | DL651: 0.038852 | DM651: 0.039933 | DN651: -0.013064 | DO651: 0.053371 | DP651: -0.048243 | DQ651: 0.078641 | DR651: -0.01884 | DS651: -0.04998 | DV651: 0.060166 | DW651: 0.013725 | DX651: 0.051247 | DY651: 0.043716 | DZ651: -0.011563 | EA651: -0.010968 | EB651: 0.107181 | EC651: 0.030363 | ED651: -0.005163 | EE651: 0.036358 | EF651: 0.054406 | EG651: 0.037926 | EH651: 0.009424 | EI651: 0.005841 | EJ651: 0.007504 | EK651: 0.018091 | EL651: -0.045445 | EM651: 0.054598 | EN651: -0.036521 | EO651: 0.062596 | EP651: -0.052353 | EQ651: -0.01718 | ER651: 0.02918 | ES651: -0.064922 | ET651: 0.00681 | EU651: -0.072194 | EV651: 0.087506 | EW651: -0.022641 | EX651: -0.065037 | EY651: 0.097577 | EZ651: 0.065188 | FA651: -0.052193 | FB651: 0.04789 | FC651: -0.022741 | FD651: 0.007548 | FE651: 0.004502 | FF651: -0.023821 | FG651: 0.074965 | FH651: 0.043995 | FI651: -0.029982 | FJ651: -0.049891 | FK651: -0.058507 | FL651: 0.075235 | FM651: 0.064448 | FN651: -0.021101 | FO651: 0.051823 | FP651: 0.054538 | FQ651: -0.026294 | FR651: 0.028052 | FS651: -0.019401 | FT651: 0.049667 | FU651: 0.019289 | FV651: 0.028512 | FW651: -0.005521 | FX651: 0.068438 | FY651: -0.070851 | FZ651: 0.047296 | GA651: -0.021506 | GB651: -0.026357
B652: =Deals!B652 -> Roper Technologies, Inc. | C652: 1 | D652: 0.154737 | E652: -0.014068 | F652: 0.115137 | G652: -0.012163 | H652: -0.075095 | I652: -0.058862 | J652: 0.14989 | K652: 0.009578 | L652: -0.08726 | M652: -0.038915 | N652: 0.068111 | O652: 0.106858 | P652: 0.007997 | Q652: 0.044866 | R652: 0.046157 | S652: -0.016404 | T652: -0.076871 | U652: 0.094822 | V652: -0.04862 | W652: 0.059701 | X652: -0.10995 | Y652: 0.0253 | Z652: 0.053567 | AA652: -0.003579 | AB652: -0.058478 | AC652: -0.108015 | AD652: 0.108045 | AE652: -0.078068 | AF652: -0.106662 | AG652: 0.154377 | AH652: 0.05874 | AI652: -0.015494 | AJ652: -0.010778 | AK652: 0.008084 | AL652: 0.024384 | AM652: 0.033522 | AN652: -0.001231 | AO652: 0.058518 | AP652: 0.026899 | AQ652: 0.012189 | AR652: -0.029616 | AS652: 0.010269 | AT652: 0.101685 | AU652: 0.012856 | AV652: -0.01361 | AW652: 0.014395 | AX652: 0.029574 | AY652: -0.086709 | AZ652: 0.041645 | BA652: 0.058 | BB652: -0.033549 | BC652: 0.017733 | BD652: 0.003662 | BE652: -0.032277 | BF652: 0.053391 | BG652: -0.082251 | BH652: 0.108926 | BI652: 0.015374 | BJ652: 0.008691 | BM652: 0.054962 | BN652: -0.008925 | BO652: 0.053871 | BP652: 0.063251 | BQ652: -0.033897 | BR652: 0.001671 | BS652: 0.095437 | BT652: 0.018008 | BU652: -0.004263 | BV652: 0.033434 | BW652: 0.050128 | BX652: 0.057761 | BY652: 0.008179 | BZ652: 0.014271 | CA652: 0.031948 | CB652: 0.041276 | CC652: -0.062381 | CD652: 0.056413 | CE652: -0.030068 | CF652: 0.052595 | CG652: -0.063404 | CH652: -0.043294 | CI652: 0.035373 | CJ652: -0.092215 | CK652: -0.003193 | CL652: -0.055016 | CM652: 0.054082 | CN652: -0.03048 | CO652: -0.053718 | CP652: 0.074071 | CQ652: 0.066348 | CR652: -0.037114 | CS652: 0.019238 | CT652: -0.021663 | CU652: 0.032915 | CV652: 0.01434 | CW652: -0.011454 | CX652: 0.054518 | CY652: 0.062584 | CZ652: -0.00811 | DA652: -0.043722 | DB652: -0.049086 | DC652: 0.069409 | DD652: 0.047821 | DE652: -0.005114 | DF652: 0.016618 | DG652: 0.064515 | DH652: 0.01242 | DI652: 0.040278 | DJ652: 0.01096 | DK652: 0.022329 | DL652: 0.038852 | DM652: 0.039933 | DN652: -0.013064 | DO652: 0.053371 | DP652: -0.048243 | DQ652: 0.078641 | DR652: -0.01884 | DS652: -0.04998 | DV652: 0.060166 | DW652: 0.013725 | DX652: 0.051247 | DY652: 0.043716 | DZ652: -0.011563 | EA652: -0.010968 | EB652: 0.107181 | EC652: 0.030363 | ED652: -0.005163 | EE652: 0.036358 | EF652: 0.054406 | EG652: 0.037926 | EH652: 0.009424 | EI652: 0.005841 | EJ652: 0.007504 | EK652: 0.018091 | EL652: -0.045445 | EM652: 0.054598 | EN652: -0.036521 | EO652: 0.062596 | EP652: -0.052353 | EQ652: -0.01718 | ER652: 0.02918 | ES652: -0.064922 | ET652: 0.00681 | EU652: -0.072194 | EV652: 0.087506 | EW652: -0.022641 | EX652: -0.065037 | EY652: 0.097577 | EZ652: 0.065188 | FA652: -0.052193 | FB652: 0.04789 | FC652: -0.022741 | FD652: 0.007548 | FE652: 0.004502 | FF652: -0.023821 | FG652: 0.074965 | FH652: 0.043995 | FI652: -0.029982 | FJ652: -0.049891 | FK652: -0.058507 | FL652: 0.075235 | FM652: 0.064448 | FN652: -0.021101 | FO652: 0.051823 | FP652: 0.054538 | FQ652: -0.026294 | FR652: 0.028052 | FS652: -0.019401 | FT652: 0.049667 | FU652: 0.019289 | FV652: 0.028512 | FW652: -0.005521 | FX652: 0.068438 | FY652: -0.070851 | FZ652: 0.047296 | GA652: -0.021506 | GB652: -0.026357
B653: =Deals!B653 -> Maxar Technologies Inc. | C653: 1 | D653: 0.195083 | E653: 0.192435 | F653: -0.009465 | G653: 0.301293 | H653: 0.077754 | I653: 0.03328 | J653: 0.079162 | K653: 0.38799 | L653: 0.084996 | M653: 0.142823 | N653: -0.209404 | O653: 0.026177 | P653: -0.19866 | Q653: 0.283923 | R653: -0.091433 | S653: -0.123518 | T653: -0.108839 | U653: -0.0625 | V653: 0.036911 | W653: 0.073011 | X653: -0.119201 | Y653: 0.247213 | Z653: 0.216708 | AA653: -0.18373 | AB653: -0.072959 | AC653: -0.125921 | AD653: 0.053277 | AE653: -0.132824 | AF653: -0.214016 | AG653: 0.193376 | AH653: 0.083259 | AI653: 1.13843 | AJ653: -0.001353 | AK653: -0.00329 | AL653: -0.00835 | AM653: 0.032511 | AN653: -0.049448 | AO653: 0.082103 | AP653: 0.102372 | AQ653: -0.042175 | AR653: -0.063858 | AS653: -0.070333 | AT653: 0.106582 | AU653: 0.156883 | AV653: -0.059712 | AW653: 0.008072 | AX653: 0.043252 | AY653: -0.067276 | AZ653: 0.055662 | BA653: -0.02875 | BB653: 0.149324 | BC653: -0.018352 | BD653: -0.009528 | BE653: -0.009615 | BF653: 0.11257 | BG653: -0.067704 | BH653: 0.025424 | BI653: -0.042389 | BJ653: -0.072074 | BM653: 0.07167 | BN653: 0.031663 | BO653: 0.02819 | BP653: 0.091547 | BQ653: -0.051048 | BR653: 0.061753 | BS653: 0.190474 | BT653: 0.071491 | BU653: 0.089893 | BV653: 0.08839 | BW653: 0.074558 | BX653: 0.012305 | BY653: 0.071065 | BZ653: 0.004465 | CA653: -0.060784 | CB653: 0.024565 | CC653: 0.033738 | CD653: 0.028453 | CE653: -0.040391 | CF653: 0.050249 | CG653: 0.003868 | CH653: 0.027265 | CI653: -0.000287 | CJ653: -0.060679 | CK653: 0.059566 | CL653: -0.128977 | CM653: 0.092258 | CN653: -0.024771 | CO653: -0.101276 | CP653: 0.157299 | CQ653: 0.014679 | CR653: -0.056763 | CS653: 0.066881 | CT653: -0.015086 | CU653: -0.100858 | CV653: -0.029129 | CW653: -0.049448 | CX653: 0.082103 | CY653: 0.102372 | CZ653: -0.042175 | DA653: -0.063858 | DB653: -0.070333 | DC653: 0.106582 | DD653: 0.156883 | DE653: -0.059712 | DF653: 0.008072 | DG653: 0.043252 | DH653: -0.067276 | DI653: 0.055662 | DJ653: -0.02875 | DK653: 0.149324 | DL653: -0.018352 | DM653: -0.009528 | DN653: -0.009615 | DO653: 0.11257 | DP653: -0.067704 | DQ653: 0.025424 | DR653: -0.042389 | DS653: -0.072074 | DV653: 0.071711 | DW653: 0.066996 | DX653: 0.020001 | DY653: 0.09015 | DZ653: -0.059242 | EA653: 0.066831 | EB653: 0.207981 | EC653: 0.066273 | ED653: 0.082058 | EE653: 0.104681 | EF653: 0.087232 | EG653: 0.018575 | EH653: 0.064895 | EI653: -0.004041 | EJ653: -0.062834 | EK653: 0.023676 | EL653: 0.038432 | EM653: 0.027954 | EN653: -0.042826 | EO653: 0.047521 | EP653: 0.005107 | EQ653: 0.031754 | ER653: 0.002859 | ES653: -0.064882 | ET653: 0.048428 | EU653: -0.118309 | EV653: 0.088304 | EW653: -0.01777 | EX653: -0.107483 | EY653: 0.153918 | EZ653: 0.014489 | FA653: -0.056602 | FB653: 0.077091 | FC653: -0.018164 | FD653: -0.10622 | FE653: -0.03736 | FF653: -0.047588 | FG653: 0.085889 | FH653: 0.103458 | FI653: -0.027839 | FJ653: -0.069414 | FK653: -0.078196 | FL653: 0.117579 | FM653: 0.155973 | FN653: -0.059929 | FO653: 0.0096 | FP653: 0.049697 | FQ653: -0.073271 | FR653: 0.057942 | FS653: -0.038418 | FT653: 0.151899 | FU653: -0.021682 | FV653: -0.00605 | FW653: -0.013066 | FX653: 0.118278 | FY653: -0.07173 | FZ653: 0.015888 | GA653: -0.041501 | GB653: -0.079441
B654: =Deals!B654 -> T-Mobile Us, Inc. | C654: 1 | D654: 0.139408 | E654: 0.041084 | F654: 0.031013 | G654: 0.086608 | H654: -0.019883 | I654: -0.041885 | J654: 0.213288 | K654: 0.014367 | L654: -0.065035 | M654: -0.048461 | N654: 0.044344 | O654: 0.054593 | P654: 0.070537 | Q654: 0.023895 | R654: -0.005593 | S654: -0.048604 | T654: -0.067581 | U654: -0.09964 | V654: -0.054073 | W654: 0.065895 | X654: -0.067339 | Y654: 0.13904 | Z654: 0.041717 | AA654: -0.040592 | AB654: 0.082427 | AC654: 0.009378 | AD654: 0.063327 | AE654: 0.006291 | AF654: -0.068005 | AG654: 0.129612 | AH654: -0.00066 | AI654: -0.075664 | AJ654: 0.0665 | AK654: -0.047753 | AL654: 0.018709 | AM654: -0.00649 | AN654: -0.046213 | AO654: 0.012022 | AP654: -0.008135 | AQ654: -0.011033 | AR654: 0.02789 | AS654: 0.027205 | AT654: 0.050327 | AU654: 0.06567 | AV654: 0.005613 | AW654: 0.01687 | AX654: -0.00049 | AY654: 0.00582 | AZ654: 0.065725 | BA654: 0.006973 | BB654: 0.034624 | BC654: 0.093757 | BD654: 0.038446 | BE654: 0.081411 | BF654: 0.110504 | BG654: -0.106139 | BH654: 0.055452 | BI654: 0.161394 | BJ654: -0.01105 | BM654: 0.054962 | BN654: -0.008925 | BO654: 0.053871 | BP654: 0.063251 | BQ654: -0.033897 | BR654: 0.001671 | BS654: 0.095437 | BT654: 0.018008 | BU654: -0.004263 | BV654: 0.033434 | BW654: 0.050128 | BX654: 0.057761 | BY654: 0.008179 | BZ654: 0.014271 | CA654: 0.031948 | CB654: 0.041276 | CC654: -0.062381 | CD654: 0.056413 | CE654: -0.030068 | CF654: 0.052595 | CG654: -0.063404 | CH654: -0.043294 | CI654: 0.035373 | CJ654: -0.092215 | CK654: -0.003193 | CL654: -0.055016 | CM654: 0.054082 | CN654: -0.03048 | CO654: -0.053718 | CP654: 0.074071 | CQ654: 0.066348 | CR654: -0.037114 | CS654: 0.019238 | CT654: -0.021663 | CU654: 0.032915 | CV654: 0.01434 | CW654: -0.011454 | CX654: 0.054518 | CY654: 0.062584 | CZ654: -0.00811 | DA654: -0.043722 | DB654: -0.049086 | DC654: 0.069409 | DD654: 0.047821 | DE654: -0.005114 | DF654: 0.016618 | DG654: 0.064515 | DH654: 0.01242 | DI654: 0.040278 | DJ654: 0.01096 | DK654: 0.022329 | DL654: 0.038852 | DM654: 0.039933 | DN654: -0.013064 | DO654: 0.053371 | DP654: -0.048243 | DQ654: 0.078641 | DR654: -0.01884 | DS654: -0.04998 | DV654: 0.060166 | DW654: 0.013725 | DX654: 0.051247 | DY654: 0.043716 | DZ654: -0.011563 | EA654: -0.010968 | EB654: 0.107181 | EC654: 0.030363 | ED654: -0.005163 | EE654: 0.036358 | EF654: 0.054406 | EG654: 0.037926 | EH654: 0.009424 | EI654: 0.005841 | EJ654: 0.007504 | EK654: 0.018091 | EL654: -0.045445 | EM654: 0.054598 | EN654: -0.036521 | EO654: 0.062596 | EP654: -0.052353 | EQ654: -0.01718 | ER654: 0.02918 | ES654: -0.064922 | ET654: 0.00681 | EU654: -0.072194 | EV654: 0.087506 | EW654: -0.022641 | EX654: -0.065037 | EY654: 0.097577 | EZ654: 0.065188 | FA654: -0.052193 | FB654: 0.04789 | FC654: -0.022741 | FD654: 0.007548 | FE654: 0.004502 | FF654: -0.023821 | FG654: 0.074965 | FH654: 0.043995 | FI654: -0.029982 | FJ654: -0.049891 | FK654: -0.058507 | FL654: 0.075235 | FM654: 0.064448 | FN654: -0.021101 | FO654: 0.051823 | FP654: 0.054538 | FQ654: -0.026294 | FR654: 0.028052 | FS654: -0.019401 | FT654: 0.049667 | FU654: 0.019289 | FV654: 0.028512 | FW654: -0.005521 | FX654: 0.068438 | FY654: -0.070851 | FZ654: 0.047296 | GA654: -0.021506 | GB654: -0.026357
